<?xml version="1.0"?>
<sdf version="1.4">
  <world name="bimanip">
    <plugin name="worldctr" filename="libworldctr.so"/>
    <!--<gravity>0 0 -9.81</gravity>-->


    <gui>
        <camera name="user_camera">
            <pose>3 7 4 0 0.4 -2</pose>
        </camera>
    </gui>
  
    <include>
      <uri>model://sun</uri>
    </include>

    <include>
      <uri>model://ground_plane</uri>
    </include>

    <model name="stuff">
      <pose>0 0 0.3 0 0 0</pose>
      <link name="l0">
        <collision name="c0">  
          <geometry><box><size>1 1 0.6</size></box></geometry>
        </collision>
        <visual name="v0">  
          <geometry><box><size>1 1 0.6</size></box></geometry>
        </visual>
      </link>
    </model>

    <model name="cargo">
      <pose>0 0 0.9 0 0 0</pose>

      <link name="l0">
        <collision name="c0">  
          <geometry><box><size>0.3 0.3 0.25</size></box></geometry>
        </collision>

        <visual name="v0">  
          <geometry><box><size>0.3 0.3 0.25</size></box></geometry>
        </visual>

        <collision name="c1">  
          <pose> 0 0 0.175 0 0 0 </pose>
          <geometry><box><size>0.6 0.3 0.1</size></box></geometry>
        </collision>

        <visual name="v1">  
          <pose> 0 0 0.175 0 0 0 </pose>
          <geometry><box><size>0.6 0.3 0.1</size></box></geometry>
        </visual>


        <collision name="c2">  
          <pose> 0 0 -0.175 0 0 0 </pose>
          <geometry><box><size>0.6 0.3 0.1</size></box></geometry>
        </collision>

        <visual name="v2">  
          <pose> 0 0 -0.175 0 0 0 </pose>
          <geometry><box><size>0.6 0.3 0.1</size></box></geometry>
        </visual>
      </link>
      <plugin name="cargo" filename="libremotectr.so"/>
    </model>

    <model name="m1">
      <pose>1 0 0.2 0 0 0</pose>

      <link name="link_0">
        <collision name="collision_0_0">
          <geometry>
            <sphere>
            	<radius>0.15</radius>
            </sphere>    
          </geometry>
        </collision>

        <visual name="visual_0_0">
          <geometry>
            <sphere>
            	<radius>0.15</radius>
            </sphere>    
          </geometry>
        </visual>
      </link>

       <link name="link_0_rod">
        <pose>0 0 0.4 0 0 0</pose>
        <collision name="collision_1_0">
          <geometry>
            <cylinder>
            	<radius>0.1</radius>
            	<length>0.8</length>
            </cylinder>
          </geometry>
        </collision>

        <visual name="visual_1_0">
          <geometry>
            <cylinder>
            	<radius>0.1</radius>
            	<length>0.8</length>
            </cylinder>
          </geometry>
        </visual>

        <inertial>
          <mass>0.01</mass>
          <inertia>
            <ixx>0.01</ixx>
            <ixy>0</ixy>
            <ixz>0</ixz>
            <iyy>0.01</iyy>
            <iyz>0</iyz>
            <izz>0.01</izz>
          </inertia>
        </inertial>
      </link>

      <link name="link_1">
        <pose>0 0 0.8 0 0 0</pose>
		    <collision name="collision_1_1">
          <geometry>
            <sphere>
            	<radius>0.15</radius>
            </sphere>          
          </geometry>
        </collision>

        <visual name="visual_1_1">
          <geometry>
            <sphere>
            	<radius>0.15</radius>
            </sphere>
          </geometry>
        </visual>

        <inertial>
          <mass>1</mass>
          <inertia>
            <ixx>1</ixx>
            <ixy>0</ixy>
            <ixz>0</ixz>
            <iyy>1</iyy>
            <iyz>0</iyz>
            <izz>1</izz>
          </inertia>
        </inertial>
      </link>

      <link name="link_1_rod">
        <pose>0 0 1.2 0 0 0</pose>
        <collision name="collision_2_0">
          <geometry>
            <cylinder>
            	<radius>0.1</radius>
            	<length>0.4</length>
            </cylinder>
          </geometry>
        </collision>

        <visual name="visual_2_0">
          <geometry>
            <cylinder>
            	<radius>0.1</radius>
            	<length>0.8</length>
            </cylinder>
          </geometry>
        </visual>

        <inertial>
          <mass>0.01</mass>
          <inertia>
            <ixx>0.01</ixx>
            <ixy>0</ixy>
            <ixz>0</ixz>
            <iyy>0.01</iyy>
            <iyz>0</iyz>
            <izz>0.01</izz>
          </inertia>
        </inertial>
      </link>

      <link name="link_2">
        <pose>0 0 1.6 0 0 0</pose>
        <inertial>
          <mass>0.001</mass>
          <inertia>
            <ixx>0.001</ixx>
            <ixy>0</ixy>
            <ixz>0</ixz>
            <iyy>0.001</iyy>
            <iyz>0</iyz>
            <izz>0.001</izz>
          </inertia>
        </inertial>
      </link>

      <link name="link_2_out">
        <pose>0 0 1.6 0 0 0</pose>
        <collision name="collision_2_1">
          <geometry>
            <sphere>
              <radius>0.15</radius>
            </sphere>          
          </geometry>
        </collision>

        <visual name="visual_2_1">
          <geometry>
            <sphere>
              <radius>0.15</radius>
            </sphere>
          </geometry>
        </visual>

        <inertial>
          <mass>1</mass>
          <inertia>
            <ixx>1</ixx>
            <ixy>0</ixy>
            <ixz>0</ixz>
            <iyy>1</iyy>
            <iyz>0</iyz>
            <izz>1</izz>
          </inertia>
        </inertial>
      </link>

      <joint name="_joint_" type="fixed">
         <parent>world</parent>
         <child>link_0</child>
      </joint>

      <joint name="j0" type="revolute">
      	 <pose> 0 0 -0.4 0 0 0 </pose>
         <parent>link_0</parent>
         <child>link_0_rod</child>
         <axis>
         	<xyz>0 1 0</xyz>
         </axis>
      </joint>

      <joint name="j01" type="fixed">
         <pose> 0 0 0 0 0 0 </pose>
         <parent>link_0_rod</parent>
         <child>link_1</child>
      </joint>

      <joint name="j1" type="revolute">
      	 <pose> 0 0 -0.4 0 0 0 </pose>
         <parent>link_1</parent>
         <child>link_1_rod</child>
         <axis>
          <xyz>0 1 0</xyz>
         </axis>
      </joint>

      <joint name="j12" type="fixed">
         <pose> 0 0 0 0 0 0 </pose>
         <parent>link_1_rod</parent>
         <child>link_2</child>
      </joint>

      <joint name="j2" type="fixed">
         <pose> 0 0 0 0 0 0 </pose>
         <parent>link_2</parent>
         <child>link_2_out</child>
      </joint>

      <plugin name="m1" filename="libremotectr.so"/>
    </model>

    <model name="m2">
      <pose>-1 0 0.2 0 0 0</pose>

      <link name="link_0">
        <collision name="collision_0_0">
          <pose>0 0 0 0 0 0</pose>
          <geometry>
            <sphere>
            	<radius>0.15</radius>
            </sphere>    
          </geometry>
        </collision>

        <visual name="visual_0_0">
          <pose>0 0 0 0 0 0</pose>
          <geometry>
            <sphere>
            	<radius>0.15</radius>
            </sphere>    
          </geometry>
        </visual>
      </link>

      <link name="link_1">
        <pose>0 0 0.4 0 0 0</pose>
        <collision name="collision_1_0">
          <pose>0 0 0 0 0 0</pose>
          <geometry>
            <cylinder>
            	<radius>0.1</radius>
            	<length>0.8</length>
            </cylinder>
          </geometry>
        </collision>

        <visual name="visual_1_0">
          <pose>0 0 0 0 0 0</pose>
          <geometry>
            <cylinder>
            	<radius>0.1</radius>
            	<length>0.8</length>
            </cylinder>
          </geometry>
        </visual>

		    <collision name="collision_1_1">
          <pose>0 0 0.4 0 0 0</pose>
          <geometry>
            <sphere>
            	<radius>0.15</radius>
            </sphere>          
          </geometry>
        </collision>

        <visual name="visual_1_1">
          <pose>0 0 0.4 0 0 0</pose>
          <geometry>
            <sphere>
            	<radius>0.15</radius>
            </sphere>
          </geometry>
        </visual>

        <inertial>
        	<pose>0 0 0 0 0 0</pose>
        </inertial>
      </link>

      <link name="link_2">
        <pose>0 0 1.2 0 0 0</pose>
        <collision name="collision_2_0">
          <pose>0 0 0 0 0 0</pose>
          <geometry>
            <cylinder>
            	<radius>0.1</radius>
            	<length>0.8</length>
            </cylinder>
          </geometry>
        </collision>

        <visual name="visual_2_0">
          <pose>0 0 0 0 0 0</pose>
          <geometry>
            <cylinder>
            	<radius>0.1</radius>
            	<length>0.8</length>
            </cylinder>
          </geometry>
        </visual>

        <inertial>
        	<pose>0 0 0 0 0 0</pose>
        </inertial>
      </link>

      <link name="link_2_d">
        <pose>0 0 1.6 0 0 0</pose>
      </link>

      <link name="link_3">
        <pose>0 0 1.6 0 0 0</pose>
        <collision name="collision_2_1">
          <pose>0 0 0 0 0 0</pose>
          <geometry>
            <sphere>
              <radius>0.15</radius>
            </sphere>          
          </geometry>
        </collision>

        <visual name="visual_2_1">
          <pose>0 0 0 0 0 0</pose>
          <geometry>
            <sphere>
              <radius>0.15</radius>
            </sphere>
          </geometry>
        </visual>

        <inertial>
          <pose>0 0 0 0 0 0</pose>
        </inertial>
      </link>

      <joint name="_joint_" type="fixed">
      	 <pose> 0 0 0 0 0 0 </pose>
         <parent>world</parent>
         <child>link_0</child>
      </joint>

      <joint name="j0" type="revolute">
      	 <pose> 0 0 -0.4 0 0 0 </pose>
         <parent>link_0</parent>
         <child>link_1</child>
         <axis>
         	<xyz>0 1 0</xyz>
         </axis>
      </joint>

      <joint name="j1" type="revolute">
      	 <pose> 0 0 -0.4 0 0 0 </pose>
         <parent>link_1</parent>
         <child>link_2</child>
         <axis>
          <xyz>0 1 0</xyz>
         </axis>
      </joint>

      <joint name="j2_pre" type="fixed">
         <pose> 0 0 0 0 0 0 </pose>
         <parent>link_2</parent>
         <child>link_2_d</child>
      </joint>

      <joint name="j2" type="fixed">
         <pose> 0 0 0 0 0 0 </pose>
         <parent>link_2_d</parent>
         <child>link_3</child>
      </joint>

      <plugin name="m2" filename="libremotectr.so"/>
    </model>
  </world>
</sdf>