<?xml version="1.0"?>
<sdf version="1.4">
  <world name="default">
    <plugin name="world" filename="libworld.so"/>

    <gravity>0 0 -1</gravity>

    <include>
      <uri>model://sun</uri>
    </include>

    <!--<model name="arr">
     <link name="arr0">
        <collision name="collision_arr_0">
          <pose>0 0 0 0 0 0</pose>
          <geometry>
            <box>
              <size>10 10 1</size>
            </box>    
          </geometry>
        </collision>

        <visual name="visual_arr_0">
          <pose>0 0 0 0 0 0</pose>
          <geometry>
            <box>
              <size>10 10 1</size>
            </box>    
          </geometry>
        </visual>
      </link>
    </model>

      <joint name="krep2" type="fixed">
         <pose> 0 0 0 0 0 0 </pose>
         <parent>world</parent>
         <child>arr</child>
      </joint>-->

    <include>
      <uri>model://ground_plane</uri>
    </include>

    
    <model name="spider">
      <plugin name="mirmik" filename="libmirmik.so"/>
      <pose>0 0 3 0 0 0</pose>

      <link name="body">
        <collision name="collision_body_0">
          <pose>0 0 0 0 0 0</pose>
          <geometry>
            <box>
            	<size>1 6 0.5</size>
            </box>    
          </geometry>
        </collision>

        <visual name="visual_body_0">
          <pose>0 0 0 0 0 0</pose>
          <geometry>
            <box>
            	<size>1 6 0.5</size>
            </box>    
          </geometry>
        </visual>
      </link>

      
	  <link name="shoulder_0">
        <collision name="collision_shoulder_0_0">
          <pose>-0.5  2.5  0  0  0  0</pose>
          <geometry>
            <sphere>
            	<radius>0.3</radius>
            </sphere>    
          </geometry>
        </collision>
  
        <visual name="visual_shoulder_0_0">
          <pose>-0.5  2.5  0  0  0  0</pose>
          <geometry>
            <sphere>
            	<radius>0.3</radius>
            </sphere>    
          </geometry>
        </visual>

        <inertial>
          <pose>-0.5  2.5  0  0  0  0</pose>
        </inertial>
      </link>


	  <link name="high_leg_0">
        <collision name="collision_high_leg_0_0">
          <pose>-1.5  2.5  0  0  0  0</pose>
          <geometry>
            <box>
            	<size>2 0.5 0.5</size>
            </box>    
          </geometry>
        </collision>
  
        <visual name="visual_high_leg_0_0">
          <pose>-1.5  2.5  0  0  0  0</pose>
          <geometry>
            <box>
            	<size>2 0.5 0.5</size>
            </box>    
          </geometry>
        </visual>

        <inertial>
          <pose>-1.5  2.5  0  0  0  0</pose>
          
  <mass> 1 </mass>
  <inertia>
    <ixx>0.05893</ixx>
    <iyy>0.33333</iyy>
    <izz>0.33333</izz>
    <ixy>0</ixy>
    <ixz>0</ixz>
    <iyz>0</iyz>
  </inertia>

        </inertial>
      </link>

      <link name="low_leg_0">
        <collision name="collision_low_leg_0_0">
          <pose>-3.5  2.5  0  0  0  0</pose>
          <geometry>
            <box>
            	<size>2 0.5 0.5</size>
            </box>    
          </geometry>
        </collision>
  
        <visual name="visual_low_leg_0_0">
          <pose>-3.5  2.5  0  0  0  0</pose>
          <geometry>
            <box>
            	<size>2 0.5 0.5</size>
            </box>    
          </geometry>
        </visual>

        <inertial>
          <pose>-3.5  2.5  0  0  0  0</pose>
          
  <mass> 1 </mass>
  <inertia>
    <ixx>0.05893</ixx>
    <iyy>0.33333</iyy>
    <izz>0.33333</izz>
    <ixy>0</ixy>
    <ixz>0</ixz>
    <iyz>0</iyz>
  </inertia>

        </inertial>
      </link>	

      <link name="fin_leg_0">
        <collision name="collision_fin_leg_0_0">
          <pose>-4.5  2.5  0  0  0  0</pose>
          <geometry>
            <sphere>
            	<radius>0.4</radius>
            </sphere>    
          </geometry>
        </collision>

          <inertial>
            <pose>-4.5  2.5  0  0  0  0</pose>
            <mass>0.1</mass>
            <inertia>
              <ixx>0.1</ixx>
              <iyy>0.1</iyy>
              <izz>0.1</izz>
              <ixy>0</ixy>
              <ixz>0</ixz>
              <iyz>0</iyz>
            </inertia>
          </inertial>
  
        <visual name="visual_fin_leg_0_0">
          <pose>-4.5  2.5  0  0  0  0</pose>
          <geometry>
            <sphere>
            	<radius>0.4</radius>
            </sphere>    
          </geometry>
        </visual>

        <inertial>
          <pose>-4.5  2.5  0  0  0  0</pose>
        </inertial>
      </link>

      <joint name="joint_shoulder_0" type="revolute">
      	 <pose> -0.5  2.5  0  0  0  0    </pose>
         <parent>body</parent>
         <child>shoulder_0</child>
         <axis>
         	<xyz>0 0 -1</xyz>
	        <use_parent_model_frame>true</use_parent_model_frame>
	     </axis>
      </joint>

      <joint name="joint_high_0" type="revolute">
      	 <pose> -0.5  2.5  0  0  0  0    </pose>
         <parent>shoulder_0</parent>
         <child>high_leg_0</child>
         <axis>
         	<xyz>0 -1 0</xyz>
	        <use_parent_model_frame>true</use_parent_model_frame>
	     </axis>
      </joint>

      <joint name="joint_low_0" type="revolute">
      	 <pose> -2.5  2.5  0  0  0  0    </pose>
         <parent>high_leg_0</parent>
         <child>low_leg_0</child>
         <axis>
          <xyz>0 -1 0</xyz>
	      <use_parent_model_frame>true</use_parent_model_frame>
         </axis>
      </joint>

      <joint name="joint_fin_0" type="fixed">
      	 <pose> -4.5  2.5  0  0  0  0    </pose>
         <parent>low_leg_0</parent>
         <child>fin_leg_0</child>
      </joint>

      
	  <link name="shoulder_1">
        <collision name="collision_shoulder_1_0">
          <pose>-0.5  0                0  0  0  0</pose>
          <geometry>
            <sphere>
            	<radius>0.3</radius>
            </sphere>    
          </geometry>
        </collision>
  
        <visual name="visual_shoulder_1_0">
          <pose>-0.5  0                0  0  0  0</pose>
          <geometry>
            <sphere>
            	<radius>0.3</radius>
            </sphere>    
          </geometry>
        </visual>

        <inertial>
          <pose>-0.5  0                0  0  0  0</pose>
        </inertial>
      </link>


	  <link name="high_leg_1">
        <collision name="collision_high_leg_1_0">
          <pose>-1.5  0                0  0  0  0</pose>
          <geometry>
            <box>
            	<size>2 0.5 0.5</size>
            </box>    
          </geometry>
        </collision>
  
        <visual name="visual_high_leg_1_0">
          <pose>-1.5  0                0  0  0  0</pose>
          <geometry>
            <box>
            	<size>2 0.5 0.5</size>
            </box>    
          </geometry>
        </visual>

        <inertial>
          <pose>-1.5  0                0  0  0  0</pose>
          
  <mass> 1 </mass>
  <inertia>
    <ixx>0.05893</ixx>
    <iyy>0.33333</iyy>
    <izz>0.33333</izz>
    <ixy>0</ixy>
    <ixz>0</ixz>
    <iyz>0</iyz>
  </inertia>

        </inertial>
      </link>

      <link name="low_leg_1">
        <collision name="collision_low_leg_1_0">
          <pose>-3.5  0                0  0  0  0</pose>
          <geometry>
            <box>
            	<size>2 0.5 0.5</size>
            </box>    
          </geometry>
        </collision>
  
        <visual name="visual_low_leg_1_0">
          <pose>-3.5  0                0  0  0  0</pose>
          <geometry>
            <box>
            	<size>2 0.5 0.5</size>
            </box>    
          </geometry>
        </visual>

        <inertial>
          <pose>-3.5  0                0  0  0  0</pose>
          
  <mass> 1 </mass>
  <inertia>
    <ixx>0.05893</ixx>
    <iyy>0.33333</iyy>
    <izz>0.33333</izz>
    <ixy>0</ixy>
    <ixz>0</ixz>
    <iyz>0</iyz>
  </inertia>

        </inertial>
      </link>	

      <link name="fin_leg_1">
        <collision name="collision_fin_leg_1_0">
          <pose>-4.5  0                0  0  0  0</pose>
          <geometry>
            <sphere>
            	<radius>0.4</radius>
            </sphere>    
          </geometry>
        </collision>

          <inertial>
            <pose>-4.5  0                0  0  0  0</pose>
            <mass>0.1</mass>
            <inertia>
              <ixx>0.1</ixx>
              <iyy>0.1</iyy>
              <izz>0.1</izz>
              <ixy>0</ixy>
              <ixz>0</ixz>
              <iyz>0</iyz>
            </inertia>
          </inertial>
  
        <visual name="visual_fin_leg_1_0">
          <pose>-4.5  0                0  0  0  0</pose>
          <geometry>
            <sphere>
            	<radius>0.4</radius>
            </sphere>    
          </geometry>
        </visual>

        <inertial>
          <pose>-4.5  0                0  0  0  0</pose>
        </inertial>
      </link>

      <joint name="joint_shoulder_1" type="revolute">
      	 <pose> -0.5  0                0  0  0  0    </pose>
         <parent>body</parent>
         <child>shoulder_1</child>
         <axis>
         	<xyz>0 0 -1</xyz>
	        <use_parent_model_frame>true</use_parent_model_frame>
	     </axis>
      </joint>

      <joint name="joint_high_1" type="revolute">
      	 <pose> -0.5  0                0  0  0  0    </pose>
         <parent>shoulder_1</parent>
         <child>high_leg_1</child>
         <axis>
         	<xyz>0 -1 0</xyz>
	        <use_parent_model_frame>true</use_parent_model_frame>
	     </axis>
      </joint>

      <joint name="joint_low_1" type="revolute">
      	 <pose> -2.5  0                0  0  0  0    </pose>
         <parent>high_leg_1</parent>
         <child>low_leg_1</child>
         <axis>
          <xyz>0 -1 0</xyz>
	      <use_parent_model_frame>true</use_parent_model_frame>
         </axis>
      </joint>

      <joint name="joint_fin_1" type="fixed">
      	 <pose> -4.5  0                0  0  0  0    </pose>
         <parent>low_leg_1</parent>
         <child>fin_leg_1</child>
      </joint>

      
	  <link name="shoulder_2">
        <collision name="collision_shoulder_2_0">
          <pose>-0.5 -2.5  0  0  0  0</pose>
          <geometry>
            <sphere>
            	<radius>0.3</radius>
            </sphere>    
          </geometry>
        </collision>
  
        <visual name="visual_shoulder_2_0">
          <pose>-0.5 -2.5  0  0  0  0</pose>
          <geometry>
            <sphere>
            	<radius>0.3</radius>
            </sphere>    
          </geometry>
        </visual>

        <inertial>
          <pose>-0.5 -2.5  0  0  0  0</pose>
        </inertial>
      </link>


	  <link name="high_leg_2">
        <collision name="collision_high_leg_2_0">
          <pose>-1.5 -2.5  0  0  0  0</pose>
          <geometry>
            <box>
            	<size>2 0.5 0.5</size>
            </box>    
          </geometry>
        </collision>
  
        <visual name="visual_high_leg_2_0">
          <pose>-1.5 -2.5  0  0  0  0</pose>
          <geometry>
            <box>
            	<size>2 0.5 0.5</size>
            </box>    
          </geometry>
        </visual>

        <inertial>
          <pose>-1.5 -2.5  0  0  0  0</pose>
          
  <mass> 1 </mass>
  <inertia>
    <ixx>0.05893</ixx>
    <iyy>0.33333</iyy>
    <izz>0.33333</izz>
    <ixy>0</ixy>
    <ixz>0</ixz>
    <iyz>0</iyz>
  </inertia>

        </inertial>
      </link>

      <link name="low_leg_2">
        <collision name="collision_low_leg_2_0">
          <pose>-3.5 -2.5  0  0  0  0</pose>
          <geometry>
            <box>
            	<size>2 0.5 0.5</size>
            </box>    
          </geometry>
        </collision>
  
        <visual name="visual_low_leg_2_0">
          <pose>-3.5 -2.5  0  0  0  0</pose>
          <geometry>
            <box>
            	<size>2 0.5 0.5</size>
            </box>    
          </geometry>
        </visual>

        <inertial>
          <pose>-3.5 -2.5  0  0  0  0</pose>
          
  <mass> 1 </mass>
  <inertia>
    <ixx>0.05893</ixx>
    <iyy>0.33333</iyy>
    <izz>0.33333</izz>
    <ixy>0</ixy>
    <ixz>0</ixz>
    <iyz>0</iyz>
  </inertia>

        </inertial>
      </link>	

      <link name="fin_leg_2">
        <collision name="collision_fin_leg_2_0">
          <pose>-4.5 -2.5  0  0  0  0</pose>
          <geometry>
            <sphere>
            	<radius>0.4</radius>
            </sphere>    
          </geometry>
        </collision>

          <inertial>
            <pose>-4.5 -2.5  0  0  0  0</pose>
            <mass>0.1</mass>
            <inertia>
              <ixx>0.1</ixx>
              <iyy>0.1</iyy>
              <izz>0.1</izz>
              <ixy>0</ixy>
              <ixz>0</ixz>
              <iyz>0</iyz>
            </inertia>
          </inertial>
  
        <visual name="visual_fin_leg_2_0">
          <pose>-4.5 -2.5  0  0  0  0</pose>
          <geometry>
            <sphere>
            	<radius>0.4</radius>
            </sphere>    
          </geometry>
        </visual>

        <inertial>
          <pose>-4.5 -2.5  0  0  0  0</pose>
        </inertial>
      </link>

      <joint name="joint_shoulder_2" type="revolute">
      	 <pose> -0.5 -2.5  0  0  0  0    </pose>
         <parent>body</parent>
         <child>shoulder_2</child>
         <axis>
         	<xyz>0 0 -1</xyz>
	        <use_parent_model_frame>true</use_parent_model_frame>
	     </axis>
      </joint>

      <joint name="joint_high_2" type="revolute">
      	 <pose> -0.5 -2.5  0  0  0  0    </pose>
         <parent>shoulder_2</parent>
         <child>high_leg_2</child>
         <axis>
         	<xyz>0 -1 0</xyz>
	        <use_parent_model_frame>true</use_parent_model_frame>
	     </axis>
      </joint>

      <joint name="joint_low_2" type="revolute">
      	 <pose> -2.5 -2.5  0  0  0  0    </pose>
         <parent>high_leg_2</parent>
         <child>low_leg_2</child>
         <axis>
          <xyz>0 -1 0</xyz>
	      <use_parent_model_frame>true</use_parent_model_frame>
         </axis>
      </joint>

      <joint name="joint_fin_2" type="fixed">
      	 <pose> -4.5 -2.5  0  0  0  0    </pose>
         <parent>low_leg_2</parent>
         <child>fin_leg_2</child>
      </joint>

      
	  <link name="shoulder_3">
        <collision name="collision_shoulder_3_0">
          <pose> 0.5  2.5  0  0  0  0</pose>
          <geometry>
            <sphere>
            	<radius>0.3</radius>
            </sphere>    
          </geometry>
        </collision>
  
        <visual name="visual_shoulder_3_0">
          <pose> 0.5  2.5  0  0  0  0</pose>
          <geometry>
            <sphere>
            	<radius>0.3</radius>
            </sphere>    
          </geometry>
        </visual>

        <inertial>
          <pose> 0.5  2.5  0  0  0  0</pose>
        </inertial>
      </link>


	  <link name="high_leg_3">
        <collision name="collision_high_leg_3_0">
          <pose> 1.5  2.5  0  0  0  0</pose>
          <geometry>
            <box>
            	<size>2 0.5 0.5</size>
            </box>    
          </geometry>
        </collision>
  
        <visual name="visual_high_leg_3_0">
          <pose> 1.5  2.5  0  0  0  0</pose>
          <geometry>
            <box>
            	<size>2 0.5 0.5</size>
            </box>    
          </geometry>
        </visual>

        <inertial>
          <pose> 1.5  2.5  0  0  0  0</pose>
          
  <mass> 1 </mass>
  <inertia>
    <ixx>0.05893</ixx>
    <iyy>0.33333</iyy>
    <izz>0.33333</izz>
    <ixy>0</ixy>
    <ixz>0</ixz>
    <iyz>0</iyz>
  </inertia>

        </inertial>
      </link>

      <link name="low_leg_3">
        <collision name="collision_low_leg_3_0">
          <pose> 3.5  2.5  0  0  0  0</pose>
          <geometry>
            <box>
            	<size>2 0.5 0.5</size>
            </box>    
          </geometry>
        </collision>
  
        <visual name="visual_low_leg_3_0">
          <pose> 3.5  2.5  0  0  0  0</pose>
          <geometry>
            <box>
            	<size>2 0.5 0.5</size>
            </box>    
          </geometry>
        </visual>

        <inertial>
          <pose> 3.5  2.5  0  0  0  0</pose>
          
  <mass> 1 </mass>
  <inertia>
    <ixx>0.05893</ixx>
    <iyy>0.33333</iyy>
    <izz>0.33333</izz>
    <ixy>0</ixy>
    <ixz>0</ixz>
    <iyz>0</iyz>
  </inertia>

        </inertial>
      </link>	

      <link name="fin_leg_3">
        <collision name="collision_fin_leg_3_0">
          <pose> 4.5  2.5  0  0  0  0</pose>
          <geometry>
            <sphere>
            	<radius>0.4</radius>
            </sphere>    
          </geometry>
        </collision>

          <inertial>
            <pose> 4.5  2.5  0  0  0  0</pose>
            <mass>0.1</mass>
            <inertia>
              <ixx>0.1</ixx>
              <iyy>0.1</iyy>
              <izz>0.1</izz>
              <ixy>0</ixy>
              <ixz>0</ixz>
              <iyz>0</iyz>
            </inertia>
          </inertial>
  
        <visual name="visual_fin_leg_3_0">
          <pose> 4.5  2.5  0  0  0  0</pose>
          <geometry>
            <sphere>
            	<radius>0.4</radius>
            </sphere>    
          </geometry>
        </visual>

        <inertial>
          <pose> 4.5  2.5  0  0  0  0</pose>
        </inertial>
      </link>

      <joint name="joint_shoulder_3" type="revolute">
      	 <pose>  0.5  2.5  0  0  0  0 </pose>
         <parent>body</parent>
         <child>shoulder_3</child>
         <axis>
         	<xyz>0 0  1</xyz>
	        <use_parent_model_frame>true</use_parent_model_frame>
	     </axis>
      </joint>

      <joint name="joint_high_3" type="revolute">
      	 <pose>  0.5  2.5  0  0  0  0 </pose>
         <parent>shoulder_3</parent>
         <child>high_leg_3</child>
         <axis>
         	<xyz>0  1 0</xyz>
	        <use_parent_model_frame>true</use_parent_model_frame>
	     </axis>
      </joint>

      <joint name="joint_low_3" type="revolute">
      	 <pose>  2.5  2.5  0  0  0  0 </pose>
         <parent>high_leg_3</parent>
         <child>low_leg_3</child>
         <axis>
          <xyz>0  1 0</xyz>
	      <use_parent_model_frame>true</use_parent_model_frame>
         </axis>
      </joint>

      <joint name="joint_fin_3" type="fixed">
      	 <pose>  4.5  2.5  0  0  0  0 </pose>
         <parent>low_leg_3</parent>
         <child>fin_leg_3</child>
      </joint>

      
	  <link name="shoulder_4">
        <collision name="collision_shoulder_4_0">
          <pose> 0.5  0                0  0  0  0</pose>
          <geometry>
            <sphere>
            	<radius>0.3</radius>
            </sphere>    
          </geometry>
        </collision>
  
        <visual name="visual_shoulder_4_0">
          <pose> 0.5  0                0  0  0  0</pose>
          <geometry>
            <sphere>
            	<radius>0.3</radius>
            </sphere>    
          </geometry>
        </visual>

        <inertial>
          <pose> 0.5  0                0  0  0  0</pose>
        </inertial>
      </link>


	  <link name="high_leg_4">
        <collision name="collision_high_leg_4_0">
          <pose> 1.5  0                0  0  0  0</pose>
          <geometry>
            <box>
            	<size>2 0.5 0.5</size>
            </box>    
          </geometry>
        </collision>
  
        <visual name="visual_high_leg_4_0">
          <pose> 1.5  0                0  0  0  0</pose>
          <geometry>
            <box>
            	<size>2 0.5 0.5</size>
            </box>    
          </geometry>
        </visual>

        <inertial>
          <pose> 1.5  0                0  0  0  0</pose>
          
  <mass> 1 </mass>
  <inertia>
    <ixx>0.05893</ixx>
    <iyy>0.33333</iyy>
    <izz>0.33333</izz>
    <ixy>0</ixy>
    <ixz>0</ixz>
    <iyz>0</iyz>
  </inertia>

        </inertial>
      </link>

      <link name="low_leg_4">
        <collision name="collision_low_leg_4_0">
          <pose> 3.5  0                0  0  0  0</pose>
          <geometry>
            <box>
            	<size>2 0.5 0.5</size>
            </box>    
          </geometry>
        </collision>
  
        <visual name="visual_low_leg_4_0">
          <pose> 3.5  0                0  0  0  0</pose>
          <geometry>
            <box>
            	<size>2 0.5 0.5</size>
            </box>    
          </geometry>
        </visual>

        <inertial>
          <pose> 3.5  0                0  0  0  0</pose>
          
  <mass> 1 </mass>
  <inertia>
    <ixx>0.05893</ixx>
    <iyy>0.33333</iyy>
    <izz>0.33333</izz>
    <ixy>0</ixy>
    <ixz>0</ixz>
    <iyz>0</iyz>
  </inertia>

        </inertial>
      </link>	

      <link name="fin_leg_4">
        <collision name="collision_fin_leg_4_0">
          <pose> 4.5  0                0  0  0  0</pose>
          <geometry>
            <sphere>
            	<radius>0.4</radius>
            </sphere>    
          </geometry>
        </collision>

          <inertial>
            <pose> 4.5  0                0  0  0  0</pose>
            <mass>0.1</mass>
            <inertia>
              <ixx>0.1</ixx>
              <iyy>0.1</iyy>
              <izz>0.1</izz>
              <ixy>0</ixy>
              <ixz>0</ixz>
              <iyz>0</iyz>
            </inertia>
          </inertial>
  
        <visual name="visual_fin_leg_4_0">
          <pose> 4.5  0                0  0  0  0</pose>
          <geometry>
            <sphere>
            	<radius>0.4</radius>
            </sphere>    
          </geometry>
        </visual>

        <inertial>
          <pose> 4.5  0                0  0  0  0</pose>
        </inertial>
      </link>

      <joint name="joint_shoulder_4" type="revolute">
      	 <pose>  0.5  0                0  0  0  0 </pose>
         <parent>body</parent>
         <child>shoulder_4</child>
         <axis>
         	<xyz>0 0  1</xyz>
	        <use_parent_model_frame>true</use_parent_model_frame>
	     </axis>
      </joint>

      <joint name="joint_high_4" type="revolute">
      	 <pose>  0.5  0                0  0  0  0 </pose>
         <parent>shoulder_4</parent>
         <child>high_leg_4</child>
         <axis>
         	<xyz>0  1 0</xyz>
	        <use_parent_model_frame>true</use_parent_model_frame>
	     </axis>
      </joint>

      <joint name="joint_low_4" type="revolute">
      	 <pose>  2.5  0                0  0  0  0 </pose>
         <parent>high_leg_4</parent>
         <child>low_leg_4</child>
         <axis>
          <xyz>0  1 0</xyz>
	      <use_parent_model_frame>true</use_parent_model_frame>
         </axis>
      </joint>

      <joint name="joint_fin_4" type="fixed">
      	 <pose>  4.5  0                0  0  0  0 </pose>
         <parent>low_leg_4</parent>
         <child>fin_leg_4</child>
      </joint>

      
	  <link name="shoulder_5">
        <collision name="collision_shoulder_5_0">
          <pose> 0.5 -2.5  0  0  0  0</pose>
          <geometry>
            <sphere>
            	<radius>0.3</radius>
            </sphere>    
          </geometry>
        </collision>
  
        <visual name="visual_shoulder_5_0">
          <pose> 0.5 -2.5  0  0  0  0</pose>
          <geometry>
            <sphere>
            	<radius>0.3</radius>
            </sphere>    
          </geometry>
        </visual>

        <inertial>
          <pose> 0.5 -2.5  0  0  0  0</pose>
        </inertial>
      </link>


	  <link name="high_leg_5">
        <collision name="collision_high_leg_5_0">
          <pose> 1.5 -2.5  0  0  0  0</pose>
          <geometry>
            <box>
            	<size>2 0.5 0.5</size>
            </box>    
          </geometry>
        </collision>
  
        <visual name="visual_high_leg_5_0">
          <pose> 1.5 -2.5  0  0  0  0</pose>
          <geometry>
            <box>
            	<size>2 0.5 0.5</size>
            </box>    
          </geometry>
        </visual>

        <inertial>
          <pose> 1.5 -2.5  0  0  0  0</pose>
          
  <mass> 1 </mass>
  <inertia>
    <ixx>0.05893</ixx>
    <iyy>0.33333</iyy>
    <izz>0.33333</izz>
    <ixy>0</ixy>
    <ixz>0</ixz>
    <iyz>0</iyz>
  </inertia>

        </inertial>
      </link>

      <link name="low_leg_5">
        <collision name="collision_low_leg_5_0">
          <pose> 3.5 -2.5  0  0  0  0</pose>
          <geometry>
            <box>
            	<size>2 0.5 0.5</size>
            </box>    
          </geometry>
        </collision>
  
        <visual name="visual_low_leg_5_0">
          <pose> 3.5 -2.5  0  0  0  0</pose>
          <geometry>
            <box>
            	<size>2 0.5 0.5</size>
            </box>    
          </geometry>
        </visual>

        <inertial>
          <pose> 3.5 -2.5  0  0  0  0</pose>
          
  <mass> 1 </mass>
  <inertia>
    <ixx>0.05893</ixx>
    <iyy>0.33333</iyy>
    <izz>0.33333</izz>
    <ixy>0</ixy>
    <ixz>0</ixz>
    <iyz>0</iyz>
  </inertia>

        </inertial>
      </link>	

      <link name="fin_leg_5">
        <collision name="collision_fin_leg_5_0">
          <pose> 4.5 -2.5  0  0  0  0</pose>
          <geometry>
            <sphere>
            	<radius>0.4</radius>
            </sphere>    
          </geometry>
        </collision>

          <inertial>
            <pose> 4.5 -2.5  0  0  0  0</pose>
            <mass>0.1</mass>
            <inertia>
              <ixx>0.1</ixx>
              <iyy>0.1</iyy>
              <izz>0.1</izz>
              <ixy>0</ixy>
              <ixz>0</ixz>
              <iyz>0</iyz>
            </inertia>
          </inertial>
  
        <visual name="visual_fin_leg_5_0">
          <pose> 4.5 -2.5  0  0  0  0</pose>
          <geometry>
            <sphere>
            	<radius>0.4</radius>
            </sphere>    
          </geometry>
        </visual>

        <inertial>
          <pose> 4.5 -2.5  0  0  0  0</pose>
        </inertial>
      </link>

      <joint name="joint_shoulder_5" type="revolute">
      	 <pose>  0.5 -2.5  0  0  0  0 </pose>
         <parent>body</parent>
         <child>shoulder_5</child>
         <axis>
         	<xyz>0 0  1</xyz>
	        <use_parent_model_frame>true</use_parent_model_frame>
	     </axis>
      </joint>

      <joint name="joint_high_5" type="revolute">
      	 <pose>  0.5 -2.5  0  0  0  0 </pose>
         <parent>shoulder_5</parent>
         <child>high_leg_5</child>
         <axis>
         	<xyz>0  1 0</xyz>
	        <use_parent_model_frame>true</use_parent_model_frame>
	     </axis>
      </joint>

      <joint name="joint_low_5" type="revolute">
      	 <pose>  2.5 -2.5  0  0  0  0 </pose>
         <parent>high_leg_5</parent>
         <child>low_leg_5</child>
         <axis>
          <xyz>0  1 0</xyz>
	      <use_parent_model_frame>true</use_parent_model_frame>
         </axis>
      </joint>

      <joint name="joint_fin_5" type="fixed">
      	 <pose>  4.5 -2.5  0  0  0  0 </pose>
         <parent>low_leg_5</parent>
         <child>fin_leg_5</child>
      </joint>


      <!--<joint name="krep" type="fixed">
         <pose> 0 0 0 0 0 0 </pose>
         <parent>world</parent>
         <child>body</child>
      </joint>-->

    </model>


  </world>
</sdf>
